[2024-01-23 05:19:02,217] {taskinstance.py:1179} INFO - Dependencies all met for <TaskInstance: docker_ex7.run_docker_container scheduled__2024-01-16T00:00:00+00:00 [queued]>
[2024-01-23 05:19:02,222] {taskinstance.py:1179} INFO - Dependencies all met for <TaskInstance: docker_ex7.run_docker_container scheduled__2024-01-16T00:00:00+00:00 [queued]>
[2024-01-23 05:19:02,222] {taskinstance.py:1376} INFO - 
--------------------------------------------------------------------------------
[2024-01-23 05:19:02,222] {taskinstance.py:1377} INFO - Starting attempt 1 of 2
[2024-01-23 05:19:02,222] {taskinstance.py:1378} INFO - 
--------------------------------------------------------------------------------
[2024-01-23 05:19:02,236] {taskinstance.py:1397} INFO - Executing <Task(DockerOperator): run_docker_container> on 2024-01-16 00:00:00+00:00
[2024-01-23 05:19:02,240] {standard_task_runner.py:52} INFO - Started process 2812 to run task
[2024-01-23 05:19:02,243] {standard_task_runner.py:79} INFO - Running: ['***', 'tasks', 'run', 'docker_ex7', 'run_docker_container', 'scheduled__2024-01-16T00:00:00+00:00', '--job-id', '56', '--raw', '--subdir', 'DAGS_FOLDER/data_cleaner/cleaner.py', '--cfg-path', '/tmp/tmpmkufmab4', '--error-file', '/tmp/tmpzc_bad8i']
[2024-01-23 05:19:02,245] {standard_task_runner.py:80} INFO - Job 56: Subtask run_docker_container
[2024-01-23 05:19:02,310] {task_command.py:371} INFO - Running <TaskInstance: docker_ex7.run_docker_container scheduled__2024-01-16T00:00:00+00:00 [running]> on host 0b2a5e032344
[2024-01-23 05:19:02,349] {taskinstance.py:1591} INFO - Exporting the following env vars:
AIRFLOW_CTX_DAG_OWNER=***
AIRFLOW_CTX_DAG_ID=docker_ex7
AIRFLOW_CTX_TASK_ID=run_docker_container
AIRFLOW_CTX_EXECUTION_DATE=2024-01-16T00:00:00+00:00
AIRFLOW_CTX_TRY_NUMBER=1
AIRFLOW_CTX_DAG_RUN_ID=scheduled__2024-01-16T00:00:00+00:00
[2024-01-23 05:19:02,360] {taskinstance.py:1909} ERROR - Task failed with exception
Traceback (most recent call last):
  File "/home/airflow/.local/lib/python3.7/site-packages/urllib3/connectionpool.py", line 710, in urlopen
    chunked=chunked,
  File "/home/airflow/.local/lib/python3.7/site-packages/urllib3/connectionpool.py", line 398, in _make_request
    conn.request(method, url, **httplib_request_kw)
  File "/usr/local/lib/python3.7/http/client.py", line 1281, in request
    self._send_request(method, url, body, headers, encode_chunked)
  File "/usr/local/lib/python3.7/http/client.py", line 1327, in _send_request
    self.endheaders(body, encode_chunked=encode_chunked)
  File "/usr/local/lib/python3.7/http/client.py", line 1276, in endheaders
    self._send_output(message_body, encode_chunked=encode_chunked)
  File "/usr/local/lib/python3.7/http/client.py", line 1036, in _send_output
    self.send(msg)
  File "/usr/local/lib/python3.7/http/client.py", line 976, in send
    self.connect()
  File "/home/airflow/.local/lib/python3.7/site-packages/docker/transport/unixconn.py", line 30, in connect
    sock.connect(self.unix_socket)
FileNotFoundError: [Errno 2] No such file or directory

During handling of the above exception, another exception occurred:

Traceback (most recent call last):
  File "/home/airflow/.local/lib/python3.7/site-packages/requests/adapters.py", line 499, in send
    timeout=timeout,
  File "/home/airflow/.local/lib/python3.7/site-packages/urllib3/connectionpool.py", line 786, in urlopen
    method, url, error=e, _pool=self, _stacktrace=sys.exc_info()[2]
  File "/home/airflow/.local/lib/python3.7/site-packages/urllib3/util/retry.py", line 550, in increment
    raise six.reraise(type(error), error, _stacktrace)
  File "/home/airflow/.local/lib/python3.7/site-packages/urllib3/packages/six.py", line 769, in reraise
    raise value.with_traceback(tb)
  File "/home/airflow/.local/lib/python3.7/site-packages/urllib3/connectionpool.py", line 710, in urlopen
    chunked=chunked,
  File "/home/airflow/.local/lib/python3.7/site-packages/urllib3/connectionpool.py", line 398, in _make_request
    conn.request(method, url, **httplib_request_kw)
  File "/usr/local/lib/python3.7/http/client.py", line 1281, in request
    self._send_request(method, url, body, headers, encode_chunked)
  File "/usr/local/lib/python3.7/http/client.py", line 1327, in _send_request
    self.endheaders(body, encode_chunked=encode_chunked)
  File "/usr/local/lib/python3.7/http/client.py", line 1276, in endheaders
    self._send_output(message_body, encode_chunked=encode_chunked)
  File "/usr/local/lib/python3.7/http/client.py", line 1036, in _send_output
    self.send(msg)
  File "/usr/local/lib/python3.7/http/client.py", line 976, in send
    self.connect()
  File "/home/airflow/.local/lib/python3.7/site-packages/docker/transport/unixconn.py", line 30, in connect
    sock.connect(self.unix_socket)
urllib3.exceptions.ProtocolError: ('Connection aborted.', FileNotFoundError(2, 'No such file or directory'))

During handling of the above exception, another exception occurred:

Traceback (most recent call last):
  File "/home/airflow/.local/lib/python3.7/site-packages/docker/api/client.py", line 214, in _retrieve_server_version
    return self.version(api_version=False)["ApiVersion"]
  File "/home/airflow/.local/lib/python3.7/site-packages/docker/api/daemon.py", line 181, in version
    return self._result(self._get(url), json=True)
  File "/home/airflow/.local/lib/python3.7/site-packages/docker/utils/decorators.py", line 46, in inner
    return f(self, *args, **kwargs)
  File "/home/airflow/.local/lib/python3.7/site-packages/docker/api/client.py", line 237, in _get
    return self.get(url, **self._set_request_timeout(kwargs))
  File "/home/airflow/.local/lib/python3.7/site-packages/requests/sessions.py", line 600, in get
    return self.request("GET", url, **kwargs)
  File "/home/airflow/.local/lib/python3.7/site-packages/requests/sessions.py", line 587, in request
    resp = self.send(prep, **send_kwargs)
  File "/home/airflow/.local/lib/python3.7/site-packages/requests/sessions.py", line 701, in send
    r = adapter.send(request, **kwargs)
  File "/home/airflow/.local/lib/python3.7/site-packages/requests/adapters.py", line 547, in send
    raise ConnectionError(err, request=request)
requests.exceptions.ConnectionError: ('Connection aborted.', FileNotFoundError(2, 'No such file or directory'))

During handling of the above exception, another exception occurred:

Traceback (most recent call last):
  File "/home/airflow/.local/lib/python3.7/site-packages/airflow/providers/docker/operators/docker.py", line 366, in execute
    self.cli = self._get_cli()
  File "/home/airflow/.local/lib/python3.7/site-packages/airflow/providers/docker/operators/docker.py", line 397, in _get_cli
    base_url=self.docker_url, version=self.api_version, tls=tls_config, timeout=self.timeout
  File "/home/airflow/.local/lib/python3.7/site-packages/docker/api/client.py", line 197, in __init__
    self._version = self._retrieve_server_version()
  File "/home/airflow/.local/lib/python3.7/site-packages/docker/api/client.py", line 222, in _retrieve_server_version
    f'Error while fetching server API version: {e}'
docker.errors.DockerException: Error while fetching server API version: ('Connection aborted.', FileNotFoundError(2, 'No such file or directory'))
[2024-01-23 05:19:02,366] {taskinstance.py:1420} INFO - Marking task as UP_FOR_RETRY. dag_id=docker_ex7, task_id=run_docker_container, execution_date=20240116T000000, start_date=20240123T051902, end_date=20240123T051902
[2024-01-23 05:19:02,371] {standard_task_runner.py:97} ERROR - Failed to execute job 56 for task run_docker_container (Error while fetching server API version: ('Connection aborted.', FileNotFoundError(2, 'No such file or directory')); 2812)
[2024-01-23 05:19:02,415] {local_task_job.py:156} INFO - Task exited with return code 1
[2024-01-23 05:19:02,430] {local_task_job.py:273} INFO - 0 downstream tasks scheduled from follow-on schedule check
